Workbook

Sheet Comparison
A1: Quick-Commerce & FMCG Financial Performance — Cross-Company Comparison
A2: Marico, Dabur, HUL | FY2020–FY2025 (FY2019 excluded — outside study window; used only as FY20 opening balance in source sheets)
A4: 1. Full Time Series (FY2020–FY2025)
A5: Metric | B5: Company | C5: FY20 | D5: FY21 | E5: FY22 | F5: FY23 | G5: FY24 | H5: FY25
A6: DIO (days) | B6: Marico | C6: =Marico!C27 -> 136.0 | D6: =Marico!D27 -> 107.1 | E6: =Marico!E27 -> 85.2 | F6: =Marico!F27 -> 89.9 | G6: =Marico!G27 -> 98.4 | H6: =Marico!H27 -> 87.1
A7: DIO (days) | B7: Dabur | C7: =Dabur!C27 -> 112.7 | D7: =Dabur!D27 -> 119.0 | E7: =Dabur!E27 -> 118.0 | F7: =Dabur!F27 -> 114.6 | G7: =Dabur!G27 -> 112.4 | H7: =Dabur!H27 -> 118.6
A8: DIO (days) | B8: HUL | C8: =HUL!C27 -> 53.4 | D8: =HUL!D27 -> 52.3 | E8: =HUL!E27 -> 54.4 | F8: =HUL!F27 -> 48.0 | G8: =HUL!G27 -> 50.7 | H8: =HUL!H27 -> 50.4
A10: DSO (days) | B10: Marico | C10: =Marico!C28 -> 26.3 | D10: =Marico!D28 -> 21.0 | E10: =Marico!E28 -> 20.0 | F10: =Marico!F28 -> 31.2 | G10: =Marico!G28 -> 39.4 | H10: =Marico!H28 -> 39.4
A11: DSO (days) | B11: Dabur | C11: =Dabur!C28 -> 34.5 | D11: =Dabur!D28 -> 26.3 | E11: =Dabur!E28 -> 20.2 | F11: =Dabur!F28 -> 23.7 | G11: =Dabur!G28 -> 25.7 | H11: =Dabur!H28 -> 26.0
A12: DSO (days) | B12: HUL | C12: =HUL!C28 -> 13.6 | D12: =HUL!D28 -> 11.3 | E12: =HUL!E28 -> 13.9 | F12: =HUL!F28 -> 16.0 | G12: =HUL!G28 -> 17.9 | H12: =HUL!H28 -> 19.7
A14: DPO (days) | B14: Marico | C14: =Marico!C29 -> 93.7 | D14: =Marico!D29 -> 90.3 | E14: =Marico!E29 -> 83.2 | F14: =Marico!F29 -> 95.4 | G14: =Marico!G29 -> 116.6 | H14: =Marico!H29 -> 99.7
A15: DPO (days) | B15: Dabur | C15: =Dabur!C29 -> 123.5 | D15: =Dabur!D29 -> 129.9 | E15: =Dabur!E29 -> 127.3 | F15: =Dabur!F29 -> 122.4 | G15: =Dabur!G29 -> 130.5 | H15: =Dabur!H29 -> 146.5
A16: DPO (days) | B16: HUL | C16: =HUL!C29 -> 147.3 | D16: =HUL!D29 -> 134.6 | E16: =HUL!E29 -> 126.7 | F16: =HUL!F29 -> 107.3 | G16: =HUL!G29 -> 123.0 | H16: =HUL!H29 -> 130.1
A18: CCC (days) | B18: Marico | C18: =Marico!C30 -> 68.7 | D18: =Marico!D30 -> 37.9 | E18: =Marico!E30 -> 22.0 | F18: =Marico!F30 -> 25.7 | G18: =Marico!G30 -> 21.3 | H18: =Marico!H30 -> 26.8
A19: CCC (days) | B19: Dabur | C19: =Dabur!C30 -> 23.7 | D19: =Dabur!D30 -> 15.4 | E19: =Dabur!E30 -> 10.9 | F19: =Dabur!F30 -> 15.8 | G19: =Dabur!G30 -> 7.7 | H19: =Dabur!H30 -> -2.0
A20: CCC (days) | B20: HUL | C20: =HUL!C30 -> -80.4 | D20: =HUL!D30 -> -71.0 | E20: =HUL!E30 -> -58.4 | F20: =HUL!F30 -> -43.2 | G20: =HUL!G30 -> -54.4 | H20: =HUL!H30 -> -60.1
A22: Gross Margin % | B22: Marico | C22: =Marico!C31 -> 48.8% | D22: =Marico!D31 -> 46.9% | E22: =Marico!E31 -> 42.9% | F22: =Marico!F31 -> 45.2% | G22: =Marico!G31 -> 50.8% | H22: =Marico!H31 -> 50.3%
A23: Gross Margin % | B23: Dabur | C23: =Dabur!C31 -> 50.1% | D23: =Dabur!D31 -> 50.1% | E23: =Dabur!E31 -> 48.2% | F23: =Dabur!F31 -> 45.6% | G23: =Dabur!G31 -> 48.0% | H23: =Dabur!H31 -> 48.0%
A24: Gross Margin % | B24: HUL | C24: =HUL!C31 -> 54.1% | D24: =HUL!D31 -> 52.9% | E24: =HUL!E31 -> 50.9% | F24: =HUL!F31 -> 47.6% | G24: =HUL!G31 -> 51.9% | H24: =HUL!H31 -> 51.6%
A26: EBITDA Margin % | B26: Marico | C26: =Marico!C32 -> 20.1% | D26: =Marico!D32 -> 19.7% | E26: =Marico!E32 -> 17.7% | F26: =Marico!F32 -> 18.5% | G26: =Marico!G32 -> 21.0% | H26: =Marico!H32 -> 19.7%
A27: EBITDA Margin % | B27: Dabur | C27: =Dabur!C32 -> 20.6% | D27: =Dabur!D32 -> 20.9% | E27: =Dabur!E32 -> 20.7% | F27: =Dabur!F32 -> 18.8% | G27: =Dabur!G32 -> 19.3% | H27: =Dabur!H32 -> 18.4%
A28: EBITDA Margin % | B28: HUL | C28: =HUL!C32 -> 24.8% | D28: =HUL!D32 -> 24.7% | E28: =HUL!E32 -> 24.5% | F28: =HUL!F32 -> 23.4% | G28: =HUL!G32 -> 23.7% | H28: =HUL!H32 -> 23.5%
A30: Net Margin % | B30: Marico | C30: =Marico!C33 -> 14.0% | D30: =Marico!D33 -> 14.6% | E30: =Marico!E33 -> 12.9% | F30: =Marico!F33 -> 13.3% | G30: =Marico!G33 -> 15.3% | H30: =Marico!H33 -> 15.0%
A31: Net Margin % | B31: Dabur | C31: =Dabur!C33 -> 16.6% | D31: =Dabur!D33 -> 17.7% | E31: =Dabur!E33 -> 16.0% | F31: =Dabur!F33 -> 14.8% | G31: =Dabur!G33 -> 14.9% | H31: =Dabur!H33 -> 14.1%
A32: Net Margin % | B32: HUL | C32: =HUL!C33 -> 17.0% | D32: =HUL!D33 -> 17.0% | E32: =HUL!E33 -> 16.9% | F32: =HUL!F33 -> 16.7% | G32: =HUL!G33 -> 16.6% | H32: =HUL!H33 -> 16.9%
A34: ROCE % | B34: Marico | C34: =Marico!C34 -> 42.4% | D34: =Marico!D34 -> 43.2% | E34: =Marico!E34 -> 43.3% | F34: =Marico!F34 -> 40.6% | G34: =Marico!G34 -> 39.4% | H34: =Marico!H34 -> 36.1%
A35: ROCE % | B35: Dabur | C35: =Dabur!C34 -> 24.8% | D35: =Dabur!D34 -> 23.8% | E35: =Dabur!E34 -> 23.7% | F35: =Dabur!F34 -> 19.5% | G35: =Dabur!G34 -> 18.8% | H35: =Dabur!H34 -> 16.2%
A36: ROCE % | B36: HUL | C36: =HUL!C34 -> 85.2% | D36: =HUL!D34 -> 30.8% | E36: =HUL!E34 -> 20.1% | F36: =HUL!F34 -> 21.6% | G36: =HUL!G34 -> 21.2% | H36: =HUL!H34 -> 20.9%
A38: ROA % | B38: Marico | C38: =Marico!C35 -> 21.0% | D38: =Marico!D35 -> 22.3% | E38: =Marico!E35 -> 21.7% | F38: =Marico!F35 -> 20.5% | G38: =Marico!G35 -> 20.6% | H38: =Marico!H35 -> 20.7%
A39: ROA % | B39: Dabur | C39: =Dabur!C35 -> 16.2% | D39: =Dabur!D35 -> 16.8% | E39: =Dabur!E35 -> 15.0% | F39: =Dabur!F35 -> 13.2% | G39: =Dabur!G35 -> 12.8% | H39: =Dabur!H35 -> 11.3%
A40: ROA % | B40: HUL | C40: =HUL!C35 -> 34.8% | D40: =HUL!D35 -> 18.0% | E40: =HUL!E35 -> 12.8% | F40: =HUL!F35 -> 14.1% | G40: =HUL!G35 -> 13.6% | H40: =HUL!H35 -> 13.4%
A42: Revenue Growth % | B42: Marico | C42: =Marico!C36 -> -0.3% | D42: =Marico!D36 -> 10.0% | E42: =Marico!E36 -> 18.2% | F42: =Marico!F36 -> 2.6% | G42: =Marico!G36 -> -1.1% | H42: =Marico!H36 -> 12.2%
A43: Revenue Growth % | B43: Dabur | C43: =Dabur!C36 -> 2.0% | D43: =Dabur!D36 -> 9.9% | E43: =Dabur!E36 -> 13.9% | F43: =Dabur!F36 -> 5.9% | G43: =Dabur!G36 -> 7.6% | H43: =Dabur!H36 -> 1.3%
A44: Revenue Growth % | B44: HUL | C44: =HUL!C36 -> 1.2% | D44: =HUL!D36 -> 18.2% | E44: =HUL!E36 -> 11.5% | F44: =HUL!F36 -> 15.5% | G44: =HUL!G36 -> 2.2% | H44: =HUL!H36 -> 2.0%
A47: 2. Pre-Period (FY20–22) vs Post-Period (FY24–25) Averages — Primary Comparison
A48: Metric | B48: Company | C48: Pre-Period Avg (FY20-22) | D48: FY23 (Transition, shown separately) | E48: Post-Period Avg (FY24-25) | F48: Abs. Change (Post - Pre) | G48: % Change | H48: Sensitivity: Post Avg incl. FY23 (FY23-25) | I48: Sensitivity % Change
A49: DIO (days) | B49: Marico | C49: =AVERAGE(Marico!C27:E27) -> 109.4 | D49: =Marico!F27 -> 89.9 | E49: =AVERAGE(Marico!G27:H27) -> 92.8 | F49: =E49-C49 -> -16.7 | G49: =IF(C49=0,"N/A",(E49-C49)/ABS(C49)) -> -15.2% | H49: =AVERAGE(Marico!F27:H27) -> 91.8 | I49: =IF(C49=0,"N/A",(H49-C49)/ABS(C49)) -> -16.1%
A50: DIO (days) | B50: Dabur | C50: =AVERAGE(Dabur!C27:E27) -> 116.6 | D50: =Dabur!F27 -> 114.6 | E50: =AVERAGE(Dabur!G27:H27) -> 115.5 | F50: =E50-C50 -> -1.0 | G50: =IF(C50=0,"N/A",(E50-C50)/ABS(C50)) -> -0.9% | H50: =AVERAGE(Dabur!F27:H27) -> 115.2 | I50: =IF(C50=0,"N/A",(H50-C50)/ABS(C50)) -> -1.2%
A51: DIO (days) | B51: HUL | C51: =AVERAGE(HUL!C27:E27) -> 53.4 | D51: =HUL!F27 -> 48.0 | E51: =AVERAGE(HUL!G27:H27) -> 50.5 | F51: =E51-C51 -> -2.8 | G51: =IF(C51=0,"N/A",(E51-C51)/ABS(C51)) -> -5.3% | H51: =AVERAGE(HUL!F27:H27) -> 49.7 | I51: =IF(C51=0,"N/A",(H51-C51)/ABS(C51)) -> -6.9%
A53: DSO (days) | B53: Marico | C53: =AVERAGE(Marico!C28:E28) -> 22.4 | D53: =Marico!F28 -> 31.2 | E53: =AVERAGE(Marico!G28:H28) -> 39.4 | F53: =E53-C53 -> 17.0 | G53: =IF(C53=0,"N/A",(E53-C53)/ABS(C53)) -> 75.6% | H53: =AVERAGE(Marico!F28:H28) -> 36.7 | I53: =IF(C53=0,"N/A",(H53-C53)/ABS(C53)) -> 63.4%
...

Sheet Dabur
A1: Dabur — Financial Data (₹ Crores, Consolidated)
A3: Line Item | B3: FY19 | C3: FY20 | D3: FY21 | E3: FY22 | F3: FY23 | G3: FY24 | H3: FY25
A4: Revenue | B4: 8533.05 | C4: 8703.59 | D4: 9561.65 | E4: 10888.68 | F4: 11529.89 | G4: 12404.01 | H4: 12563.09
A5: Other income | B5: 296.17 | C5: 305.29 | D5: 325.29 | E5: 393.16 | F5: 445.39 | G5: 482.41 | H5: 550.1
A6: Cost of materials consumed | B6: 3475.35 | C6: 3731.71 | D6: 3998.58 | E6: 4766.12 | F6: 5306.97 | G6: 5186.9 | H6: 5263.68
A7: Purchases of stock-in-trade | B7: 802.98 | C7: 674.62 | D7: 982.53 | E7: 882.12 | F7: 1052.49 | G7: 1211.11 | H7: 1328.28
A8: Changes in inventories | B8: 12.64 | C8: -65.04 | D8: -207.2 | E8: -8.55 | F8: -90.79 | G8: 48.95 | H8: -57.1
A9: Finance costs | B9: 59.58 | C9: 49.54 | D9: 30.81 | E9: 38.6 | F9: 78.24 | G9: 124.18 | H9: 163.5
A10: D&A | B10: 176.9 | C10: 220.45 | D10: 240.13 | E10: 252.89 | F10: 310.96 | G10: 399.21 | H10: 445.6
A11: PBEIT (Profit before Exceptional Items & Tax) | B11: 1800.21 | C11: 1827.64 | D11: 2056.02 | E11: 2353.68 | F11: 2218.68 | G11: 2358.74 | H11: 2257.89
A12: Net Profit (attributable to Owners) | B12: 1442.33 | C12: 1444.96 | D12: 1693.3 | E12: 1739.22 | F12: 1707.15 | G12: 1842.68 | H12: 1767.63
A13: Inventory | B13: 1300.53 | C13: 1379.57 | D13: 1734.28 | E13: 1911.37 | F13: 2024.2 | G13: 1946.97 | H13: 2300.11
A14: Trade Receivables | B14: 833.56 | C14: 813.89 | D14: 561.58 | E14: 646.15 | F14: 848.75 | G14: 898.72 | H14: 888.5
A15: Trade Payables | B15: 1455.43 | C15: 1482.15 | D15: 1915.26 | E15: 2017.95 | F15: 2186.61 | G15: 2421.71 | H15: 2825.34
... A18: PBT (reported, for reference only — not used in derived metrics) | B18: 1724.87 | C18: 1727.64 | D18: 2056.02 | E18: 2268.68 | F18: 2218.68 | G18: 2358.74 | H18: 2257.89
A19: Derived (calculated)
A20: COGS | B20: =B6+B7+B8 -> 4,290.97 | C20: =C6+C7+C8 -> 4,341.29 | D20: =D6+D7+D8 -> 4,773.91 | E20: =E6+E7+E8 -> 5,639.69 | F20: =F6+F7+F8 -> 6,268.67 | G20: =G6+G7+G8 -> 6,446.96 | H20: =H6+H7+H8 -> 6,534.86
A21: Gross Profit | B21: =B4-B20 -> 4,242.08 | C21: =C4-C20 -> 4,362.30 | D21: =D4-D20 -> 4,787.74 | E21: =E4-E20 -> 5,248.99 | F21: =F4-F20 -> 5,261.22 | G21: =G4-G20 -> 5,957.05 | H21: =H4-H20 -> 6,028.23
A22: EBITDA | B22: =B11+B9+B10-B5 -> 1,740.52 | C22: =C11+C9+C10-C5 -> 1,792.34 | D22: =D11+D9+D10-D5 -> 2,001.67 | E22: =E11+E9+E10-E5 -> 2,252.01 | F22: =F11+F9+F10-F5 -> 2,162.49 | G22: =G11+G9+G10-G5 -> 2,399.72 | H22: =H11+H9+H10-H5 -> 2,316.89
A23: EBIT | B23: =B22-B10 -> 1,563.62 | C23: =C22-C10 -> 1,571.89 | D23: =D22-D10 -> 1,761.54 | E23: =E22-E10 -> 1,999.12 | F23: =F22-F10 -> 1,851.53 | G23: =G22-G10 -> 2,000.51 | H23: =H22-H10 -> 1,871.29
A24: Capital Employed | B24: =B16-B17 -> 5,776.33 | C24: =C16-C17 -> 6,890.13 | D24: =D16-D17 -> 7,912.94 | E24: =E16-E17 -> 8,961.99 | F24: =F16-F17 -> 10,044.94 | G24: =G16-G17 -> 11,192.25 | H24: =H16-H17 -> 11,913.84
A26: Ratios & Metrics
A27: DIO (days) | B27: N/A | C27: =((B13+C13)/2)/C20*365 -> 112.7 | D27: =((C13+D13)/2)/D20*365 -> 119.0 | E27: =((D13+E13)/2)/E20*365 -> 118.0 | F27: =((E13+F13)/2)/F20*365 -> 114.6 | G27: =((F13+G13)/2)/G20*365 -> 112.4 | H27: =((G13+H13)/2)/H20*365 -> 118.6
A28: DSO (days) | B28: N/A | C28: =((B14+C14)/2)/C4*365 -> 34.5 | D28: =((C14+D14)/2)/D4*365 -> 26.3 | E28: =((D14+E14)/2)/E4*365 -> 20.2 | F28: =((E14+F14)/2)/F4*365 -> 23.7 | G28: =((F14+G14)/2)/G4*365 -> 25.7 | H28: =((G14+H14)/2)/H4*365 -> 26.0
A29: DPO (days) | B29: N/A | C29: =((B15+C15)/2)/C20*365 -> 123.5 | D29: =((C15+D15)/2)/D20*365 -> 129.9 | E29: =((D15+E15)/2)/E20*365 -> 127.3 | F29: =((E15+F15)/2)/F20*365 -> 122.4 | G29: =((F15+G15)/2)/G20*365 -> 130.5 | H29: =((G15+H15)/2)/H20*365 -> 146.5
A30: CCC (days) | B30: N/A | C30: =C27+C28-C29 -> 23.7 | D30: =D27+D28-D29 -> 15.4 | E30: =E27+E28-E29 -> 10.9 | F30: =F27+F28-F29 -> 15.8 | G30: =G27+G28-G29 -> 7.7 | H30: =H27+H28-H29 -> -2.0
A31: Gross Margin % | B31: =B21/B4 -> 49.7% | C31: =C21/C4 -> 50.1% | D31: =D21/D4 -> 50.1% | E31: =E21/E4 -> 48.2% | F31: =F21/F4 -> 45.6% | G31: =G21/G4 -> 48.0% | H31: =H21/H4 -> 48.0%
A32: EBITDA Margin % | B32: =B22/B4 -> 20.4% | C32: =C22/C4 -> 20.6% | D32: =D22/D4 -> 20.9% | E32: =E22/E4 -> 20.7% | F32: =F22/F4 -> 18.8% | G32: =G22/G4 -> 19.3% | H32: =H22/H4 -> 18.4%
A33: Net Margin % | B33: =B12/B4 -> 16.9% | C33: =C12/C4 -> 16.6% | D33: =D12/D4 -> 17.7% | E33: =E12/E4 -> 16.0% | F33: =F12/F4 -> 14.8% | G33: =G12/G4 -> 14.9% | H33: =H12/H4 -> 14.1%
A34: ROCE % | B34: N/A | C34: =(C23)/(((B16-B17)+C24)/2) -> 24.8% | D34: =D23/((C24+D24)/2) -> 23.8% | E34: =E23/((D24+E24)/2) -> 23.7% | F34: =F23/((E24+F24)/2) -> 19.5% | G34: =G23/((F24+G24)/2) -> 18.8% | H34: =H23/((G24+H24)/2) -> 16.2%
A35: ROA % | B35: N/A | C35: =C12/((B16+C16)/2) -> 16.2% | D35: =D12/((C16+D16)/2) -> 16.8% | E35: =E12/((D16+E16)/2) -> 15.0% | F35: =F12/((E16+F16)/2) -> 13.2% | G35: =G12/((F16+G16)/2) -> 12.8% | H35: =H12/((G16+H16)/2) -> 11.3%
A36: Revenue Growth % | C36: =(C4-B4)/B4 -> 2.0% | D36: =(D4-C4)/C4 -> 9.9% | E36: =(E4-D4)/D4 -> 13.9% | F36: =(F4-E4)/E4 -> 5.9% | G36: =(G4-F4)/F4 -> 7.6% | H36: =(H4-G4)/G4 -> 1.3%

Sheet Marico
A1: Marico — Financial Data (₹ Crores, Consolidated)
A3: Line Item | B3: FY19 | C3: FY20 | D3: FY21 | E3: FY22 | F3: FY23 | G3: FY24 | H3: FY25
A4: Revenue | B4: 7334 | C4: 7315 | D4: 8048 | E4: 9512 | F4: 9764 | G4: 9653 | H4: 10831
A5: Other income | B5: 103 | C5: 124 | D5: 94 | E5: 98 | F5: 144 | G5: 142 | H5: 208
A6: Cost of materials consumed | B6: 3995 | C6: 3428 | D6: 3884 | E6: 5061 | F6: 4649 | G6: 3941 | H6: 4572
A7: Purchases of stock-in-trade | B7: 145 | C7: 177 | D7: 339 | E7: 491 | F7: 541 | G7: 752 | H7: 960
A8: Changes in inventories | B8: -123 | C8: 140 | D8: 47 | E8: -116 | F8: 161 | G8: 55 | H8: -144
A9: Finance costs | B9: 24 | C9: 50 | D9: 34 | E9: 39 | F9: 56 | G9: 73 | H9: 53
A10: D&A | B10: 96 | C10: 140 | D10: 139 | E10: 139 | F10: 155 | G10: 158 | H10: 178
A11: PBEIT (Profit before Exceptional Items & Tax) | B11: 1263 | C11: 1403 | D11: 1510 | E11: 1601 | F11: 1743 | G11: 1937 | H11: 2116
A12: Net Profit (attributable to Owners) | B12: 1118 | C12: 1021 | D12: 1172 | E12: 1225 | F12: 1302 | G12: 1481 | H12: 1629
A13: Inventory | B13: 1411 | C13: 1380 | D13: 1126 | E13: 1412 | F13: 1225 | G13: 1336 | H13: 1235
A14: Trade Receivables | B14: 517 | C14: 539 | D14: 388 | E14: 652 | F14: 1015 | G14: 1069 | H14: 1271
A15: Trade Payables | B15: 944 | C15: 978 | D15: 1134 | E15: 1344 | F15: 1452 | G15: 1581 | H15: 1363
... A18: PBT (reported, for reference only — not used in derived metrics) | B18: 1263 | C18: 1374 | D18: 1523 | E18: 1601 | F18: 1743 | G18: 1937 | H18: 2116
A19: Derived (calculated)
A20: COGS | B20: =B6+B7+B8 -> 4,017.00 | C20: =C6+C7+C8 -> 3,745.00 | D20: =D6+D7+D8 -> 4,270.00 | E20: =E6+E7+E8 -> 5,436.00 | F20: =F6+F7+F8 -> 5,351.00 | G20: =G6+G7+G8 -> 4,748.00 | H20: =H6+H7+H8 -> 5,388.00
A21: Gross Profit | B21: =B4-B20 -> 3,317.00 | C21: =C4-C20 -> 3,570.00 | D21: =D4-D20 -> 3,778.00 | E21: =E4-E20 -> 4,076.00 | F21: =F4-F20 -> 4,413.00 | G21: =G4-G20 -> 4,905.00 | H21: =H4-H20 -> 5,443.00
A22: EBITDA | B22: =B11+B9+B10-B5 -> 1,280.00 | C22: =C11+C9+C10-C5 -> 1,469.00 | D22: =D11+D9+D10-D5 -> 1,589.00 | E22: =E11+E9+E10-E5 -> 1,681.00 | F22: =F11+F9+F10-F5 -> 1,810.00 | G22: =G11+G9+G10-G5 -> 2,026.00 | H22: =H11+H9+H10-H5 -> 2,139.00
A23: EBIT | B23: =B22-B10 -> 1,184.00 | C23: =C22-C10 -> 1,329.00 | D23: =D22-D10 -> 1,450.00 | E23: =E22-E10 -> 1,542.00 | F23: =F22-F10 -> 1,655.00 | G23: =G22-G10 -> 1,868.00 | H23: =H22-H10 -> 1,961.00
A24: Capital Employed | B24: =B16-B17 -> 3,056.00 | C24: =C16-C17 -> 3,217.00 | D24: =D16-D17 -> 3,497.00 | E24: =E16-E17 -> 3,633.00 | F24: =F16-F17 -> 4,517.00 | G24: =G16-G17 -> 4,977.00 | H24: =H16-H17 -> 5,877.00
A26: Ratios & Metrics
A27: DIO (days) | B27: N/A | C27: =((B13+C13)/2)/C20*365 -> 136.0 | D27: =((C13+D13)/2)/D20*365 -> 107.1 | E27: =((D13+E13)/2)/E20*365 -> 85.2 | F27: =((E13+F13)/2)/F20*365 -> 89.9 | G27: =((F13+G13)/2)/G20*365 -> 98.4 | H27: =((G13+H13)/2)/H20*365 -> 87.1
A28: DSO (days) | B28: N/A | C28: =((B14+C14)/2)/C4*365 -> 26.3 | D28: =((C14+D14)/2)/D4*365 -> 21.0 | E28: =((D14+E14)/2)/E4*365 -> 20.0 | F28: =((E14+F14)/2)/F4*365 -> 31.2 | G28: =((F14+G14)/2)/G4*365 -> 39.4 | H28: =((G14+H14)/2)/H4*365 -> 39.4
A29: DPO (days) | B29: N/A | C29: =((B15+C15)/2)/C20*365 -> 93.7 | D29: =((C15+D15)/2)/D20*365 -> 90.3 | E29: =((D15+E15)/2)/E20*365 -> 83.2 | F29: =((E15+F15)/2)/F20*365 -> 95.4 | G29: =((F15+G15)/2)/G20*365 -> 116.6 | H29: =((G15+H15)/2)/H20*365 -> 99.7
A30: CCC (days) | B30: N/A | C30: =C27+C28-C29 -> 68.7 | D30: =D27+D28-D29 -> 37.9 | E30: =E27+E28-E29 -> 22.0 | F30: =F27+F28-F29 -> 25.7 | G30: =G27+G28-G29 -> 21.3 | H30: =H27+H28-H29 -> 26.8
A31: Gross Margin % | B31: =B21/B4 -> 45.2% | C31: =C21/C4 -> 48.8% | D31: =D21/D4 -> 46.9% | E31: =E21/E4 -> 42.9% | F31: =F21/F4 -> 45.2% | G31: =G21/G4 -> 50.8% | H31: =H21/H4 -> 50.3%
A32: EBITDA Margin % | B32: =B22/B4 -> 17.5% | C32: =C22/C4 -> 20.1% | D32: =D22/D4 -> 19.7% | E32: =E22/E4 -> 17.7% | F32: =F22/F4 -> 18.5% | G32: =G22/G4 -> 21.0% | H32: =H22/H4 -> 19.7%
A33: Net Margin % | B33: =B12/B4 -> 15.2% | C33: =C12/C4 -> 14.0% | D33: =D12/D4 -> 14.6% | E33: =E12/E4 -> 12.9% | F33: =F12/F4 -> 13.3% | G33: =G12/G4 -> 15.3% | H33: =H12/H4 -> 15.0%
A34: ROCE % | B34: N/A | C34: =(C23)/(((B16-B17)+C24)/2) -> 42.4% | D34: =D23/((C24+D24)/2) -> 43.2% | E34: =E23/((D24+E24)/2) -> 43.3% | F34: =F23/((E24+F24)/2) -> 40.6% | G34: =G23/((F24+G24)/2) -> 39.4% | H34: =H23/((G24+H24)/2) -> 36.1%
A35: ROA % | B35: N/A | C35: =C12/((B16+C16)/2) -> 21.0% | D35: =D12/((C16+D16)/2) -> 22.3% | E35: =E12/((D16+E16)/2) -> 21.7% | F35: =F12/((E16+F16)/2) -> 20.5% | G35: =G12/((F16+G16)/2) -> 20.6% | H35: =H12/((G16+H16)/2) -> 20.7%
A36: Revenue Growth % | C36: =(C4-B4)/B4 -> -0.3% | D36: =(D4-C4)/C4 -> 10.0% | E36: =(E4-D4)/D4 -> 18.2% | F36: =(F4-E4)/E4 -> 2.6% | G36: =(G4-F4)/F4 -> -1.1% | H36: =(H4-G4)/G4 -> 12.2%

Sheet HUL
A1: HUL — Financial Data (₹ Crores, Consolidated)
A3: Line Item | B3: FY19 | C3: FY20 | D3: FY21 | E3: FY22 | F3: FY23 | G3: FY24 | H3: FY25
A4: Revenue | B4: 39310 | C4: 39783 | D4: 47028 | E4: 52446 | F4: 60580 | G4: 61896 | H4: 63121
A5: Other income | B5: 550 | C5: 632 | D5: 410 | E5: 258 | F5: 512 | G5: 811 | H5: 1017
A6: Cost of materials consumed | B6: 13707 | C6: 11976 | D6: 15432 | E6: 16446 | F6: 20212 | G6: 19257 | H6: 19458
A7: Purchases of stock-in-trade | B7: 4755 | C7: 6391 | D7: 7121 | E7: 9311 | F7: 11579 | G7: 10514 | H7: 11273
A8: Changes in inventories | B8: 12 | C8: -108 | D8: -405 | E8: -22 | F8: -75 | G8: -11 | H8: -153
A9: Finance costs | B9: 33 | C9: 118 | D9: 117 | E9: 106 | F9: 114 | G9: 334 | H9: 395
A10: D&A | B10: 565 | C10: 1002 | D10: 1074 | E10: 1091 | F10: 1137 | G10: 1216 | H10: 1355
A11: PBEIT (Profit before Exceptional Items & Tax) | B11: 8832 | C11: 9373 | D11: 10845 | E11: 11918 | F11: 13409 | G11: 13920 | H11: 14110
A12: Net Profit (attributable to Owners) | B12: 6054 | C12: 6748 | D12: 7995 | E12: 8879 | F12: 10120 | G12: 10277 | H12: 10649
A13: Inventory | B13: 2574 | C13: 2767 | D13: 3579 | E13: 4096 | F13: 4251 | G13: 4022 | H13: 4415
A14: Trade Receivables | B14: 1816 | C14: 1149 | D14: 1758 | E14: 2236 | F14: 3079 | G14: 2997 | H14: 3819
A15: Trade Payables | B15: 7206 | C15: 7535 | D15: 8802 | E15: 9068 | F15: 9574 | G15: 10486 | H15: 11315
... A18: PBT (reported, for reference only — not used in derived metrics) | B18: 8604 | C18: 9173 | D18: 10606 | E18: 11874 | F18: 13345 | G18: 13926 | H18: 14415
A19: Derived (calculated)
A20: COGS | B20: =B6+B7+B8 -> 18,474.00 | C20: =C6+C7+C8 -> 18,259.00 | D20: =D6+D7+D8 -> 22,148.00 | E20: =E6+E7+E8 -> 25,735.00 | F20: =F6+F7+F8 -> 31,716.00 | G20: =G6+G7+G8 -> 29,760.00 | H20: =H6+H7+H8 -> 30,578.00
A21: Gross Profit | B21: =B4-B20 -> 20,836.00 | C21: =C4-C20 -> 21,524.00 | D21: =D4-D20 -> 24,880.00 | E21: =E4-E20 -> 26,711.00 | F21: =F4-F20 -> 28,864.00 | G21: =G4-G20 -> 32,136.00 | H21: =H4-H20 -> 32,543.00
A22: EBITDA | B22: =B11+B9+B10-B5 -> 8,880.00 | C22: =C11+C9+C10-C5 -> 9,861.00 | D22: =D11+D9+D10-D5 -> 11,626.00 | E22: =E11+E9+E10-E5 -> 12,857.00 | F22: =F11+F9+F10-F5 -> 14,148.00 | G22: =G11+G9+G10-G5 -> 14,659.00 | H22: =H11+H9+H10-H5 -> 14,843.00
A23: EBIT | B23: =B22-B10 -> 8,315.00 | C23: =C22-C10 -> 8,859.00 | D23: =D22-D10 -> 10,552.00 | E23: =E22-E10 -> 11,766.00 | F23: =F22-F10 -> 13,011.00 | G23: =G22-G10 -> 13,443.00 | H23: =H22-H10 -> 13,488.00
A24: Capital Employed | B24: =B16-B17 -> 9,962.00 | C24: =C16-C17 -> 10,836.00 | D24: =D16-D17 -> 57,654.00 | E24: =E16-E17 -> 59,237.00 | F24: =F16-F17 -> 61,059.00 | G24: =G16-G17 -> 65,623.00 | H24: =H16-H17 -> 63,343.00
A26: Ratios & Metrics
A27: DIO (days) | B27: N/A | C27: =((B13+C13)/2)/C20*365 -> 53.4 | D27: =((C13+D13)/2)/D20*365 -> 52.3 | E27: =((D13+E13)/2)/E20*365 -> 54.4 | F27: =((E13+F13)/2)/F20*365 -> 48.0 | G27: =((F13+G13)/2)/G20*365 -> 50.7 | H27: =((G13+H13)/2)/H20*365 -> 50.4
A28: DSO (days) | B28: N/A | C28: =((B14+C14)/2)/C4*365 -> 13.6 | D28: =((C14+D14)/2)/D4*365 -> 11.3 | E28: =((D14+E14)/2)/E4*365 -> 13.9 | F28: =((E14+F14)/2)/F4*365 -> 16.0 | G28: =((F14+G14)/2)/G4*365 -> 17.9 | H28: =((G14+H14)/2)/H4*365 -> 19.7
A29: DPO (days) | B29: N/A | C29: =((B15+C15)/2)/C20*365 -> 147.3 | D29: =((C15+D15)/2)/D20*365 -> 134.6 | E29: =((D15+E15)/2)/E20*365 -> 126.7 | F29: =((E15+F15)/2)/F20*365 -> 107.3 | G29: =((F15+G15)/2)/G20*365 -> 123.0 | H29: =((G15+H15)/2)/H20*365 -> 130.1
A30: CCC (days) | B30: N/A | C30: =C27+C28-C29 -> -80.4 | D30: =D27+D28-D29 -> -71.0 | E30: =E27+E28-E29 -> -58.4 | F30: =F27+F28-F29 -> -43.2 | G30: =G27+G28-G29 -> -54.4 | H30: =H27+H28-H29 -> -60.1
A31: Gross Margin % | B31: =B21/B4 -> 53.0% | C31: =C21/C4 -> 54.1% | D31: =D21/D4 -> 52.9% | E31: =E21/E4 -> 50.9% | F31: =F21/F4 -> 47.6% | G31: =G21/G4 -> 51.9% | H31: =H21/H4 -> 51.6%
A32: EBITDA Margin % | B32: =B22/B4 -> 22.6% | C32: =C22/C4 -> 24.8% | D32: =D22/D4 -> 24.7% | E32: =E22/E4 -> 24.5% | F32: =F22/F4 -> 23.4% | G32: =G22/G4 -> 23.7% | H32: =H22/H4 -> 23.5%
A33: Net Margin % | B33: =B12/B4 -> 15.4% | C33: =C12/C4 -> 17.0% | D33: =D12/D4 -> 17.0% | E33: =E12/E4 -> 16.9% | F33: =F12/F4 -> 16.7% | G33: =G12/G4 -> 16.6% | H33: =H12/H4 -> 16.9%
A34: ROCE % | B34: N/A | C34: =(C23)/(((B16-B17)+C24)/2) -> 85.2% | D34: =D23/((C24+D24)/2) -> 30.8% | E34: =E23/((D24+E24)/2) -> 20.1% | F34: =F23/((E24+F24)/2) -> 21.6% | G34: =G23/((F24+G24)/2) -> 21.2% | H34: =H23/((G24+H24)/2) -> 20.9%
A35: ROA % | B35: N/A | C35: =C12/((B16+C16)/2) -> 34.8% | D35: =D12/((C16+D16)/2) -> 18.0% | E35: =E12/((D16+E16)/2) -> 12.8% | F35: =F12/((E16+F16)/2) -> 14.1% | G35: =G12/((F16+G16)/2) -> 13.6% | H35: =H12/((G16+H16)/2) -> 13.4%
A36: Revenue Growth % | C36: =(C4-B4)/B4 -> 1.2% | D36: =(D4-C4)/C4 -> 18.2% | E36: =(E4-D4)/D4 -> 11.5% | F36: =(F4-E4)/E4 -> 15.5% | G36: =(G4-F4)/F4 -> 2.2% | H36: =(H4-G4)/G4 -> 2.0%

Sheet Charts
A1: Chart Compendium — Quick-Commerce & FMCG Financial Performance (Marico · Dabur · HUL, FY2020–FY2025)
A2: All six analysis charts compiled below. Source data: Comparison / Marico / Dabur / HUL sheets.
A4: Chart 1 — Working Capital Cycle: DIO, DSO, DPO (lines) & CCC (bars), FY2020–FY2025
A27: Chart 2 — Cash Conversion Cycle Across Companies, FY2020–FY2025
A61: Chart 3 — Profitability Margin Trends (Gross / EBITDA / Net), FY2020–FY2025
A83: Chart 4 — Return Metrics: ROCE & ROA, FY2020–FY2025
A110: Chart 5 — Pre-Period vs Post-Period Averages (FY23 excluded)
A146: Chart 6 — Revenue Growth (YoY %), FY2020–FY2025
